<?xml version="1.0" ?>
<robot name="fish" xmlns:xacro="http://www.ros.org/wiki/xacro">
<!-- All links coordinates are initially all at origin O. Each of the fish model component is centered at its geometric center in Blender,
 and links are saved separately as stl. -->
  <link name="p1">
    <self_collide>0</self_collide>
    <inertial>
      <mass value="100"/>
      <inertia ixx="1.67E-03" ixy="0" ixz="0" iyy="0.02166" iyz="0" izz="0.02166"/>
      <origin xyz="0 0 0." />
    </inertial>
    <visual>
      <origin rpy="0 0 0" xyz="0 0 0"/>
      <geometry>
        <mesh filename="package://fine-fish-10/fish-01.stl"/>
      </geometry>
    </visual>
    <collision>
      <origin rpy="0 0 0" xyz="0 0 0"/>
      <geometry>
        <mesh filename="package://fine-fish-10/fish-01.stl"/>
      </geometry>
    </collision>
  </link>

  <!-- Displayed in utils function axiscreator. -->
  <joint name="joint1" type="revolute">
    <parent link="p1"/>
    <child link="p2"/>
    <!-- P1_O: The xyz below is the position of joint1 (P1) in O frame. -->
    <origin rpy="0 0 0" xyz="0 0.211 0"/> 
    <axis xyz="1 0 0"/>
    <limit effort="1000" lower="-.5" upper=".5" velocity="50"/>
    <dynamics damping="0.001" friction="0.001"/>
  </joint>

  <link name="p2">
    <self_collide>0</self_collide>
    <inertial>
      <mass value="100"/>
      <inertia ixx="1.67E-03" ixy="0" ixz="0" iyy="0.02166" iyz="0" izz="0.02166"/>
      <origin xyz="0 0 0." />
    </inertial>
    <visual>
      <!-- -P1_O : The xyz below is -P1_O, making link2 (p2) go back to the initially aligned position. -->
      <origin rpy="0 0 0" xyz="0.138 0.203 0.001"/>
      <geometry>
        <mesh filename="package://fine-fish-10/fish-02.stl"/>
      </geometry>
    </visual>
    <collision>
      <origin rpy="0 0 0" xyz="0.138 0.203 0.001"/>
      <geometry>
        <mesh filename="package://fine-fish-10/fish-02.stl"/>
      </geometry>
    </collision>
  </link>

  <joint name="joint2" type="revolute">
    <parent link="p2"/>
    <child link="p3"/>
    <origin rpy="0 0 0" xyz="0 0.354 0"/> 
    <axis xyz="1 0 0"/>
    <limit effort="1000" lower="-.4" upper=".4" velocity="50"/>
    <dynamics damping="0.001" friction="0.001"/>
  </joint>

  <link name="p3">
    <self_collide>0</self_collide>
    <inertial>
      <mass value="100"/>
      <inertia ixx="1.67E-03" ixy="0" ixz="0" iyy="0.02166" iyz="0" izz="0.02166"/>
      <origin xyz="0 0 0." />
    </inertial>
    <visual>
      <origin rpy="0 0 0" xyz="0.216 0.288 0.004"/>
      <geometry>
        <mesh filename="package://fine-fish-10/fish-03.stl"/>
      </geometry>
    </visual>
    <collision>
      <origin rpy="0 0 0" xyz="0.216 0.288 0.004"/>
      <geometry>
        <mesh filename="package://fine-fish-10/fish-03.stl"/>
      </geometry>
    </collision>
  </link>

  <joint name="joint3" type="revolute">
    <parent link="p3"/>
    <child link="p4"/>
    <origin rpy="0 0 0" xyz="0 0.494 0"/> 
    <axis xyz="1 0 0"/>
    <limit effort="1000" lower="-.3" upper=".3" velocity="50"/>
    <dynamics damping="0.001" friction="0.001"/>
  </joint>

  <link name="p4">
    <self_collide>0</self_collide>
    <inertial>
      <mass value="100"/>
      <inertia ixx="1.67E-03" ixy="0" ixz="0" iyy="0.02166" iyz="0" izz="0.02166"/>
      <origin xyz="0 0 0." />
    </inertial>
    <visual>
      <origin rpy="0 0 0" xyz="0.195 0.231 0"/>
      <geometry>
        <mesh filename="package://fine-fish-10/fish-04.stl"/>
      </geometry>
    </visual>
    <collision>
      <origin rpy="0 0 0" xyz="0.195 0.231 0.002"/>
      <geometry>
        <mesh filename="package://fine-fish-10/fish-04.stl"/>
      </geometry>
    </collision>
  </link>

  <joint name="joint4" type="revolute">
    <parent link="p4"/>
    <child link="p5"/>
    <origin rpy="0 0 0" xyz="0 0.494 0"/> 
    <axis xyz="1 0 0"/>
    <limit effort="1000" lower="-.25" upper=".25" velocity="50"/>
    <dynamics damping="0.001" friction="0.001"/>
  </joint>

  <link name="p5">
    <self_collide>0</self_collide>
    <inertial>
      <mass value="100"/>
      <inertia ixx="1.67E-03" ixy="0" ixz="0" iyy="0.02166" iyz="0" izz="0.02166"/>
      <origin xyz="0 0 0." />
    </inertial>
    <visual>
      <origin rpy="0 0 0" xyz="0.200 0.268 0"/>
      <geometry>
        <mesh filename="package://fine-fish-10/fish-05.stl"/>
      </geometry>
    </visual>
    <collision>
      <origin rpy="0 0 0" xyz="0.200 0.268 0"/>
      <geometry>
        <mesh filename="package://fine-fish-10/fish-05.stl"/>
      </geometry>
    </collision>
  </link>

  <joint name="joint5" type="revolute">
    <parent link="p5"/>
    <child link="p6"/>
    <origin rpy="0 0 0" xyz="0 0.494 0"/> 
    <axis xyz="1 0 0"/>
    <limit effort="1000" lower="-.25" upper=".25" velocity="50"/>
    <dynamics damping="0.001" friction="0.001"/>
  </joint>

  <link name="p6">
    <self_collide>0</self_collide>
    <inertial>
      <mass value="100"/>
      <inertia ixx="1.67E-03" ixy="0" ixz="0" iyy="0.02166" iyz="0" izz="0.02166"/>
      <origin xyz="0 0 0." />
    </inertial>
    <visual>
      <origin rpy="0 0 0" xyz="0.169 0.228 -0.007"/>
      <geometry>
        <mesh filename="package://fine-fish-10/fish-06.stl"/>
      </geometry>
    </visual>
    <collision>
      <origin rpy="0 0 0" xyz="0.169 0.228 -0.007"/>
      <geometry>
        <mesh filename="package://fine-fish-10/fish-06.stl"/>
      </geometry>
    </collision>
  </link>

  <joint name="joint6" type="revolute">
    <parent link="p6"/>
    <child link="p7"/>
    <origin rpy="0 0 0" xyz="0 0.457 0"/> 
    <axis xyz="1 0 0"/>
    <limit effort="1000" lower="-.2" upper=".2" velocity="50"/>
    <dynamics damping="0.001" friction="0.001"/>
  </joint>

  <link name="p7">
    <self_collide>0</self_collide>
    <inertial>
      <mass value="100"/>
      <inertia ixx="1.67E-03" ixy="0" ixz="0" iyy="0.02166" iyz="0" izz="0.02166"/>
      <origin xyz="0 0 0." />
    </inertial>
    <visual>
      <origin rpy="0 0 0" xyz="0.083 0.220 0"/>
      <geometry>
        <mesh filename="package://fine-fish-10/fish-07.stl"/>
      </geometry>
    </visual>
    <collision>
      <origin rpy="0 0 0" xyz="0.083 0.220 0"/>
      <geometry>
        <mesh filename="package://fine-fish-10/fish-07.stl"/>
      </geometry>
    </collision>
  </link>

  <joint name="joint7" type="revolute">
    <parent link="p7"/>
    <child link="p8"/>
    <origin rpy="0 0 0" xyz="0 0.457 0"/> 
    <axis xyz="1 0 0"/>
    <limit effort="1000" lower="-.2" upper=".2" velocity="50"/>
    <dynamics damping="0.001" friction="0.001"/>
  </joint>

  <link name="p8">
    <self_collide>0</self_collide>
    <inertial>
      <mass value="100"/>
      <inertia ixx="1.67E-03" ixy="0" ixz="0" iyy="0.02166" iyz="0" izz="0.02166"/>
      <origin xyz="0 0 0." />
    </inertial>
    <visual>
      <origin rpy="0 0 0" xyz="0.171 0.220 0"/>
      <geometry>
        <mesh filename="package://fine-fish-10/fish-08.stl"/>
      </geometry>
    </visual>
    <collision>
      <origin rpy="0 0 0" xyz="0.171 0.220 0"/>
      <geometry>
        <mesh filename="package://fine-fish-10/fish-08.stl"/>
      </geometry>
    </collision>
  </link>

  <joint name="joint8" type="revolute">
    <parent link="p8"/>
    <child link="p9"/>
    <origin rpy="0 0 0" xyz="0 0.457 0"/> 
    <axis xyz="1 0 0"/>
    <limit effort="1000" lower="-.15" upper=".15" velocity="50"/>
    <dynamics damping="0.001" friction="0.001"/>
  </joint>

  <link name="p9">
    <self_collide>0</self_collide>
    <inertial>
      <mass value="100"/>
      <inertia ixx="1.67E-03" ixy="0" ixz="0" iyy="0.02166" iyz="0" izz="0.02166"/>
      <origin xyz="0 0 0." />
    </inertial>
    <visual>
      <origin rpy="0 0 0" xyz="0.126 0.205 -0.012"/>
      <geometry>
        <mesh filename="package://fine-fish-10/fish-09.stl"/>
      </geometry>
    </visual>
    <collision>
      <origin rpy="0 0 0" xyz="0.126 0.205 -0.012"/>
      <geometry>
        <mesh filename="package://fine-fish-10/fish-09.stl"/>
      </geometry>
    </collision>
  </link>

  <joint name="joint9" type="revolute">
    <parent link="p9"/>
    <child link="p10"/>
    <origin rpy="0 0 0" xyz="0 0.457 0"/> 
    <axis xyz="1 0 0"/>
    <limit effort="1000" lower="-.1" upper=".1" velocity="50"/>
    <dynamics damping="0.001" friction="0.001"/>
  </joint>

  <link name="p10">
    <self_collide>0</self_collide>
    <inertial>
      <mass value="100"/>
      <inertia ixx="1.67E-03" ixy="0" ixz="0" iyy="0.02166" iyz="0" izz="0.02166"/>
      <origin xyz="0 0 0." />
    </inertial>
    <visual>
      <origin rpy="0 0 0" xyz="0.129 0.232 -0.015"/>
      <geometry>
        <mesh filename="package://fine-fish-10/fish-10.stl"/>
      </geometry>
    </visual>
    <collision>
      <origin rpy="0 0 0" xyz="0.129 0.232 -0.015"/>
      <geometry>
        <mesh filename="package://fine-fish-10/fish-10.stl"/>
      </geometry>
    </collision>
  </link>

</robot>