<?xml version="1.0" ?>
<robot name="fish" xmlns:xacro="http://www.ros.org/wiki/xacro">
<!-- All links coordinates are initially all at origin O. The fish model in Blender should 
be aligned at World origin and links are saved separately as stl. -->
  <link name="p1">
    <visual>
      <origin rpy="0 0 0" xyz="0 0 0"/>
      <geometry>
        <mesh filename="package://fine-fish/fish3p1.stl"/>
      </geometry>
    </visual>
    <collision>
      <origin rpy="0 0 0" xyz="0 0 0"/>
      <geometry>
        <mesh filename="package://fine-fish/fish3p1.stl"/>
      </geometry>
    </collision>
  </link>

  <!-- Displayed in utils function axiscreator. -->
  <joint name="joint1" type="revolute">
    <parent link="p1"/>
    <child link="p2"/>
    <!-- P1_O: The xyz below is the position of joint1 (P1) in O frame. -->
    <origin rpy="0 0 0" xyz="-0.74 0 0"/> 
    <axis xyz="0 1 0"/>
    <limit effort="20" lower="-1.5" upper="1.5" velocity="0.2"/>
  </joint>

  <link name="p2">
    <visual>
      <!-- -P1_O : The xyz below is -P1_O, making link2 (p2) go back to the initially aligned position. -->
      <origin rpy="0 0 0" xyz="0.74 0 -0.0"/>
      <geometry>
        <mesh filename="package://fine-fish/fish3p2.stl"/>
      </geometry>
    </visual>
    <collision>
      <origin rpy="0 0 0" xyz="0.74 0 -0.0"/>
      <geometry>
        <mesh filename="package://fine-fish/fish3p2.stl"/>
      </geometry>
    </collision>
  </link>

  <!-- values in the frame of O1. -->
  <joint name="joint2" type="revolute">
    <parent link="p2"/>
    <child link="p3"/>
    <!-- P2_O1: The xyz below is the position of joint2 (P2) in O1. -->
    <origin rpy="0 0 0" xyz="1.5 0 0"/>
    <axis xyz="0 1 0"/>
    <limit effort="20" lower="-1.5" upper="1.5" velocity="0.2"/>
  </joint>

  <link name="p3">
    <visual>
    <!-- -P2_O = -(P1_O + P2_O1) : The xyz below is the minus of P2 in O. -->
      <origin rpy="0 0 0" xyz="-0.76 0 -0.0"/>
      <geometry>
        <mesh filename="package://fine-fish/fish3p3.stl"/>
      </geometry>
    </visual>
    <collision>
      <origin rpy="0 0 0" xyz="-0.76 0 -0.0"/>
      <geometry>
        <mesh filename="package://fine-fish/fish3p3.stl"/>
      </geometry>
    </collision>
  </link>
</robot>
