<robot name="my_robot">
  <!-- <link name="world"/>

  <joint name="joint0" type="floating">
    <origin rpy="0 0 0" xyz="0 0 0.0"/>
    <parent link="world"/>
    <child link="tail"/>
    <limit effort="30" velocity="1.0"/>
  </joint> -->

  <!-- the model -->
  <link name="tail">
    <inertial>
      <mass value="0.01" />
      <origin xyz="0 0 0." />
      <inertia ixx="50.0" ixy="0.0" ixz="0.0"
        iyy="50.0" iyz="0.0"
        izz="50.0" />
    </inertial>
    <visual>
      <origin rpy="0 0 0" xyz="0 0 0."/>
      <geometry>
        <box size="0.01 0.2 0.4" /> 
      </geometry>
    </visual>
    <collision>
      <origin rpy="0 0 0" xyz="0 0 0"/>
      <geometry>
        <box size="0.01 0.2 0.4" />
      </geometry>
    </collision>
  </link>

  <joint name="joint0" type="revolute">
    <axis xyz="0 0 1"/>
    <limit effort="1000.0" lower="-.5" upper=".5" velocity="0.5"/>
    <origin rpy="0 0 0" xyz="0 0.08 0"/>
    <parent link="tail"/>
    <child link="link0"/>
  </joint>

  <link name="link0">
    <inertial>
      <mass value="0.01" />
      <origin xyz="0 0 0." />
      <inertia ixx="50.0" ixy="0.0" ixz="0.0"
        iyy="50.0" iyz="0.0"
        izz="50.0" />
    </inertial>
    <visual>
      <origin rpy="0 0 0" xyz="0 0.1 0"/>
      <geometry>
        <box size="0.06 0.2 0.1" /> 
      </geometry>
    </visual>
    <collision>
      <origin rpy="0 0 0" xyz="0 0.1 0"/>
      <geometry>
        <box size="0.06 0.2 0.1" />
      </geometry>
    </collision>
  </link>

  <joint name="joint1" type="revolute">
    <axis xyz="0 0 1"/>
    <limit effort="1000.0" lower="-.5" upper=".5" velocity="0.5"/>
    <origin rpy="0 0 0" xyz="0 0.18 0"/>
    <parent link="link0"/>
    <child link="link1"/>
  </joint>

  <link name="link1">
    <inertial>
        <origin rpy="0 0 0" xyz="0 0.1 0"/>
        <mass value="0.1"/>
        <inertia ixx="1.67E-03" ixy="0" ixz="0" iyy="0.02166" iyz="0" izz="0.02166"/>
    </inertial>
    <visual>
        <origin rpy="0 0 0" xyz="0 0.1 0"/>
        <geometry>
          <box size="0.1 0.2 0.3" />
        </geometry>
        <material name="">
            <color rgba="0 0 1 0.3"/>
        </material>
    </visual>
    <collision>
        <origin rpy="0 0 0" xyz="0 0.1 0"/>
        <geometry>
            <box size=".1 0.2 0.3" />
        </geometry>
    </collision>
  </link>

  <joint name="joint2" type="revolute">
    <axis xyz="0 0 1"/>
    <limit effort="1000.0" lower="-.5" upper=".5" velocity="0.5"/>
    <origin rpy="0 0 0" xyz="0 0.18 0"/>
    <parent link="link1"/>
    <child link="link2"/>
  </joint>

  <link name="link2">
    <inertial>
        <origin rpy="0 0 0" xyz="0 0.1 0"/>
        <mass value="0.1"/>
        <inertia ixx="1.67E-03" ixy="0" ixz="0" iyy="0.02166" iyz="0" izz="0.02166"/>
    </inertial>
    <visual>
        <origin rpy="0 0 0" xyz="0 0.1 0"/>
        <geometry>
          <box size="0.12 0.2 0.4" />
        </geometry>
        <material name="">
            <color rgba="0 0 1 0.4"/>
        </material>
    </visual>
    <collision>
        <origin rpy="0 0 0" xyz="0 0.1 0"/>
        <geometry>
            <box size="0.12 0.2 0.4" />
        </geometry>
    </collision>
  </link>

  <joint name="joint3" type="revolute">
    <axis xyz="0 0 1"/>
    <limit effort="1000.0" lower="-.5" upper=".5" velocity="0.5"/>
    <origin rpy="0 0 0" xyz="0 0.18 0"/>
    <parent link="link2"/>
    <child link="link3"/>
  </joint>

  <link name="link3">
    <inertial>
        <origin rpy="0 0 0" xyz="0 0.1 0"/>
        <mass value="0.1"/>
        <inertia ixx="1.67E-03" ixy="0" ixz="0" iyy="0.02166" iyz="0" izz="0.02166"/>
    </inertial>
    <visual>
        <origin rpy="0 0 0" xyz="0 0.1 0"/>
        <geometry>
          <box size="0.14 0.2 0.5" />
        </geometry>
        <material name="">
            <color rgba="0 0 1 0.5"/>
        </material>
    </visual>
    <collision>
        <origin rpy="0 0 0" xyz="0 0.1 0"/>
        <geometry>
            <box size="0.14 0.2 0.5" />
        </geometry>
    </collision>
  </link>

  <joint name="joint4" type="revolute">
    <axis xyz="0 0 1"/>
    <limit effort="1000.0" lower="-.5" upper=".5" velocity="0.5"/>
    <origin rpy="0 0 0" xyz="0 0.18 0"/>
    <parent link="link3"/>
    <child link="link4"/>
  </joint>

  <link name="link4">
    <inertial>
        <origin rpy="0 0 0" xyz="0 0.1 0"/>
        <mass value="0.1"/>
        <inertia ixx="1.67E-03" ixy="0" ixz="0" iyy="0.02166" iyz="0" izz="0.02166"/>
    </inertial>
    <visual>
        <origin rpy="0 0 0" xyz="0 0.1 0"/>
        <geometry>
          <box size="0.16 0.2 0.6" />
        </geometry>
        <material name="">
            <color rgba="0 0 1 0.5"/>
        </material>
    </visual>
    <collision>
        <origin rpy="0 0 0" xyz="0 0.1 0"/>
        <geometry>
            <box size="0.16 0.2 0.6" />
        </geometry>
    </collision>
  </link>

  <joint name="joint5" type="revolute">
    <axis xyz="0 0 1"/>
    <limit effort="1000.0" lower="-.5" upper=".5" velocity="0.5"/>
    <origin rpy="0 0 0" xyz="0 0.18 0"/>
    <parent link="link4"/>
    <child link="link5"/>
  </joint>

  <link name="link5">
    <inertial>
        <origin rpy="0 0 0" xyz="0 0.1 0"/>
        <mass value="0.1"/>
        <inertia ixx="1.67E-03" ixy="0" ixz="0" iyy="0.02166" iyz="0" izz="0.02166"/>
    </inertial>
    <visual>
        <origin rpy="0 0 0" xyz="0 0.1 0"/>
        <geometry>
          <box size="0.18 0.2 0.7" />
        </geometry>
        <material name="">
            <color rgba="0 0 1 0.5"/>
        </material>
    </visual>
    <collision>
        <origin rpy="0 0 0" xyz="0 0.1 0"/>
        <geometry>
            <box size="0.18 0.2 0.7" />
        </geometry>
    </collision>
  </link>

  <joint name="joint6" type="revolute">
    <axis xyz="0 0 1"/>
    <limit effort="1000.0" lower="-.5" upper=".5" velocity="0.5"/>
    <origin rpy="0 0 0" xyz="0 0.18 0"/>
    <parent link="link5"/>
    <child link="link6"/>
  </joint>

  <link name="link6">
    <inertial>
        <origin rpy="0 0 0" xyz="0 0.1 0"/>
        <mass value="0.1"/>
        <inertia ixx="1.67E-03" ixy="0" ixz="0" iyy="0.02166" iyz="0" izz="0.02166"/>
    </inertial>
    <visual>
        <origin rpy="0 0 0" xyz="0 0.1 0"/>
        <geometry>
          <box size="0.21 0.2 0.75" />
        </geometry>
        <material name="">
            <color rgba="0 0 1 0.5"/>
        </material>
    </visual>
    <collision>
        <origin rpy="0 0 0" xyz="0 0.1 0"/>
        <geometry>
            <box size="0.21 0.2 0.75" />
        </geometry>
    </collision>
  </link>

  <joint name="joint7" type="revolute">
    <axis xyz="0 0 1"/>
    <limit effort="1000.0" lower="-.5" upper=".5" velocity="0.5"/>
    <origin rpy="0 0 0" xyz="0 0.18 0"/>
    <parent link="link6"/>
    <child link="link7"/>
  </joint>

  <link name="link7">
    <inertial>
        <origin rpy="0 0 0" xyz="0 0.1 0"/>
        <mass value="0.1"/>
        <inertia ixx="1.67E-03" ixy="0" ixz="0" iyy="0.02166" iyz="0" izz="0.02166"/>
    </inertial>
    <visual>
        <origin rpy="0 0 0" xyz="0 0.1 0"/>
        <geometry>
          <box size="0.18 0.2 0.65" />
        </geometry>
        <material name="">
            <color rgba="0 0 1 0.5"/>
        </material>
    </visual>
    <collision>
        <origin rpy="0 0 0" xyz="0 0.1 0"/>
        <geometry>
            <box size="0.18 0.2 0.65" />
        </geometry>
    </collision>
  </link>

  <joint name="joint8" type="revolute">
    <axis xyz="0 0 1"/>
    <limit effort="1000.0" lower="-.5" upper=".5" velocity="0.5"/>
    <origin rpy="0 0 0" xyz="0 0.18 0"/>
    <parent link="link7"/>
    <child link="link8"/>
  </joint>

  <link name="link8">
    <inertial>
        <origin rpy="0 0 0" xyz="0 0.1 0"/>
        <mass value="0.1"/>
        <inertia ixx="1.67E-03" ixy="0" ixz="0" iyy="0.02166" iyz="0" izz="0.02166"/>
    </inertial>
    <visual>
        <origin rpy="0 0 0" xyz="0 0.1 0"/>
        <geometry>
          <box size="0.17 0.2 0.5" />
        </geometry>
        <material name="">
            <color rgba="0 0 1 0.5"/>
        </material>
    </visual>
    <collision>
        <origin rpy="0 0 0" xyz="0 0.1 0"/>
        <geometry>
            <box size="0.17 0.2 0.5" />
        </geometry>
    </collision>
  </link>

  <joint name="joint9" type="revolute">
    <axis xyz="0 0 1"/>
    <limit effort="1000.0" lower="-.5" upper=".5" velocity="0.5"/>
    <origin rpy="0 0 0" xyz="0 0.18 0"/>
    <parent link="link8"/>
    <child link="link9"/>
  </joint>

  <link name="link9">
    <inertial>
        <origin rpy="0 0 0" xyz="0 0.1 0"/>
        <mass value="0.1"/>
        <inertia ixx="1.67E-03" ixy="0" ixz="0" iyy="0.02166" iyz="0" izz="0.02166"/>
    </inertial>
    <visual>
        <origin rpy="0 0 0" xyz="0 0.1 0"/>
        <geometry>
          <box size="0.16 0.2 0.35" />
        </geometry>
        <material name="">
            <color rgba="0 0 1 0.5"/>
        </material>
    </visual>
    <collision>
        <origin rpy="0 0 0" xyz="0 0.1 0"/>
        <geometry>
            <box size="0.16 0.2 0.35" />
        </geometry>
    </collision>
  </link>

  <joint name="joint10" type="revolute">
    <axis xyz="0 0 1"/>
    <limit effort="1000.0" lower="-.5" upper=".5" velocity="0.5"/>
    <origin rpy="0 0 0" xyz="0 0.18 0"/>
    <parent link="link9"/>
    <child link="link10"/>
  </joint>

  <link name="link10">
    <inertial>
        <origin rpy="0 0 0" xyz="0 0.1 0"/>
        <mass value="0.5"/>
        <inertia ixx="1.67E-03" ixy="0" ixz="0" iyy="0.02166" iyz="0" izz="0.02166"/>
    </inertial>
    <visual>
        <origin rpy="0 0 0" xyz="0 0.1 0"/>
        <geometry>
          <box size="0.15 0.2 0.2" />
        </geometry>
        <material name="">
            <color rgba="0 0 1 0.5"/>
        </material>
    </visual>
    <collision>
        <origin rpy="0 0 0" xyz="0 0.1 0"/>
        <geometry>
            <box size="0.15 0.2 0.2" />
        </geometry>
    </collision>
  </link>

  <joint name="joint11" type="revolute">
    <axis xyz="0 0 1"/>
    <limit effort="1000.0" lower="-.5" upper=".5" velocity="0.5"/>
    <origin rpy="0 0 0" xyz="0 0.28 -0.05"/>
    <parent link="link10"/>
    <child link="link11"/>
  </joint>

  <link name="link11">
    <visual>
      <geometry>
        <mesh filename="package://fish/ring.dae" scale=".02 .02 .02"/>
      </geometry>
    </visual>
    <collision>
      <geometry>
        <mesh filename="package://fish/ring.stl" scale=".02 .02 .02"/>
      </geometry>
    </collision>
  </link>


  <!-- ROS Control plugin for Gazebo -->
  <gazebo>
    <plugin name="gazebo_ros_control" filename="libgazebo_ros_control.so">
      <robotNamespace>/my_robot</robotNamespace>
      <legacyModeNS>false</legacyModeNS>
    </plugin>
    <plugin name="object_controller" filename="libgazebo_ros_planar_move.so">
      <commandTopic>cmd_vel</commandTopic>
      <odometryTopic>odom</odometryTopic>
      <odometryFrame>odom</odometryFrame>
      <odometryRate>20.0</odometryRate>
      <robotBaseFrame>base_footprint</robotBaseFrame>
    </plugin>
  </gazebo>

  <!-- transmission -->
  <!-- <transmission name="trans_joint0">
      <type>transmission_interface/SimpleTransmission</type>
      <joint name="joint0">
          <hardwareInterface>hardware_interface/PositionJointInterface</hardwareInterface>
      </joint>
      <actuator name="joint0_motor">
          <hardwareInterface>hardware_interface/PositionJointInterface</hardwareInterface>
          <mechanicalReduction>1</mechanicalReduction>
      </actuator>
  </transmission> -->
  <!-- <transmission name="trans_joint1">
      <type>transmission_interface/SimpleTransmission</type>
      <joint name="joint1">
          <hardwareInterface>hardware_interface/PositionJointInterface</hardwareInterface>
      </joint>
      <actuator name="joint1_motor">
          <hardwareInterface>hardware_interface/PositionJointInterface</hardwareInterface>
          <mechanicalReduction>1</mechanicalReduction>
      </actuator>
  </transmission>
  <transmission name="trans_joint2">
      <type>transmission_interface/SimpleTransmission</type>
      <joint name="joint2">
          <hardwareInterface>hardware_interface/PositionJointInterface</hardwareInterface>
      </joint>
      <actuator name="joint2_motor">
          <hardwareInterface>hardware_interface/PositionJointInterface</hardwareInterface>
          <mechanicalReduction>1</mechanicalReduction>
      </actuator>
  </transmission> -->

</robot>