<?xml version="1.0"?>
<robot name="starfish">

  <link name="central">
    <inertial>
      <mass value="100"/>
      <inertia ixx="1E-00" ixy="0" ixz="0" iyy="1E-00" iyz="0" izz="1E-00"/>
      <origin xyz="0 0 0." />
    </inertial>
    <visual>
      <origin rpy="0 0 0" xyz="0 0 0"/>
      <geometry>
        <mesh filename="package://starfish-soft/central.stl" scale="1 1 1"/>
      </geometry>
    </visual>
    <collision>
      <origin rpy="0 0 0" xyz="0 0 0"/>
      <geometry>
        <mesh filename="package://starfish-soft/central.stl" scale="1 1 1" />
      </geometry>
    </collision>
  </link>


  <joint name="joint11" type="revolute">
    <parent link="central"/>
    <child link="mid1"/>
    <origin rpy="0 0 0" xyz="0 0.368 0"/> 
    <axis xyz="0 0 1"/> 
    <limit effort="1000" lower="-.5" upper=".5" velocity="50"/>
    <dynamics damping="0.001" friction="0.001"/>
  </joint>
  <link name="mid1">
    <inertial>
      <mass value="1"/>
      <inertia ixx="1E-03" ixy="0" ixz="0" iyy="1E-03" iyz="0" izz="1E-03"/>
      <origin xyz="0 0 0." />
    </inertial>
    <visual>
      <origin rpy="0 0 0" xyz="0 0 0"/>
      <geometry>
        <box size="0.01 0.01 0.01" />
      </geometry>
    </visual>
    <collision>
      <origin rpy="0 0 0" xyz="0 0 0"/>
      <geometry>
        <box size="0.01 0.01 0.01" />
      </geometry>
    </collision>
  </link>

  <joint name="joint12" type="revolute">
    <parent link="mid1"/>
    <child link="arm1"/>
    <origin rpy="0 0 0" xyz="0 0 0"/> 
    <axis xyz="0.99939 0.0349 0"/> 
    <limit effort="1000" lower="-1.5" upper="1.5" velocity="50"/>
    <dynamics damping="0.001" friction="0.001"/>
  </joint>
  <link name="arm1">
    <inertial>
      <mass value="50"/>
      <inertia ixx="1E-02" ixy="0" ixz="0" iyy="1E01" iyz="0" izz="1E-02"/>
      <origin xyz="0 0.74 0" />
    </inertial>
    <visual>
      <origin rpy="0 0 0" xyz="0 -0.368 0"/>
      <geometry>
        <mesh filename="package://starfish-soft/arm1.stl" scale="1 1 1"/>
      </geometry>
    </visual>
    <collision>
      <origin rpy="0 0 0" xyz="0 -0.368 0"/>
      <geometry>
        <mesh filename="package://starfish-soft/arm1.stl" scale="1 1 1" />
      </geometry>
    </collision>
  </link>


  <joint name="joint21" type="revolute">
    <parent link="central"/>
    <child link="mid2"/>
    <origin rpy="0 0 0" xyz="0.274 0.112 0"/> 
    <axis xyz="0 0 1"/>
    <limit effort="1000" lower="-.5" upper=".5" velocity="50"/>
    <dynamics damping="0.001" friction="0.001"/>
  </joint>
  <link name="mid2">
    <inertial>
      <mass value="1"/>
      <inertia ixx="1E-03" ixy="0" ixz="0" iyy="1E-03" iyz="0" izz="1E-03"/>
      <origin xyz="0 0 0." />
    </inertial>
    <visual>
      <origin rpy="0 0 0" xyz="0 0 0"/>
      <geometry>
        <box size="0.01 0.01 0.01" />
      </geometry>
    </visual>
    <collision>
      <origin rpy="0 0 0" xyz="0 0 0"/>
      <geometry>
        <box size="0.01 0.01 0.01" />
      </geometry>
    </collision>
  </link>

  <joint name="joint22" type="revolute">
    <parent link="mid2"/>
    <child link="arm2"/>
    <origin rpy="0 0 0" xyz="0 0 0"/> 
    <axis xyz="0.37415 -0.92718 0"/>
    <limit effort="1000" lower="-.5" upper=".5" velocity="50"/>
    <dynamics damping="0.001" friction="0.001"/>
  </joint>
  <link name="arm2">
    <inertial>
      <mass value="50"/>
      <inertia ixx="1E00" ixy="0" ixz="0" iyy="1E01" iyz="0" izz="1E-02"/>
      <origin xyz="0.548 0.224 0." />
    </inertial>
    <visual>
      <origin rpy="0 0 0" xyz="-0.274 -0.112 0"/>
      <geometry>
        <mesh filename="package://starfish-soft/arm2.stl" scale="1 1 1"/>
      </geometry>
    </visual>
    <collision>
      <origin rpy="0 0 0" xyz="-0.274 -0.112 0"/>
      <geometry>
        <mesh filename="package://starfish-soft/arm2.stl" scale="1 1 1" />
      </geometry>
    </collision>
  </link>


  <joint name="joint31" type="revolute">
    <parent link="central"/>
    <child link="mid3"/>
    <origin rpy="0 0 0" xyz="-0.295 0.100 0"/> 
    <axis xyz="0 0 1"/>
    <limit effort="1000" lower="-.5" upper=".5" velocity="50"/>
    <dynamics damping="0.001" friction="0.001"/>
  </joint>
  <link name="mid3">
    <inertial>
      <mass value="1"/>
      <inertia ixx="1E-03" ixy="0" ixz="0" iyy="1E-03" iyz="0" izz="1E-03"/>
      <origin xyz="0 0 0." />
    </inertial>
    <visual>
      <origin rpy="0 0 0" xyz="0 0 0"/>
      <geometry>
        <box size="0.01 0.01 0.01" />
      </geometry>
    </visual>
    <collision>
      <origin rpy="0 0 0" xyz="0 0 0"/>
      <geometry>
        <box size="0.01 0.01 0.01" />
      </geometry>
    </collision>
  </link>

  <joint name="joint32" type="revolute">
    <parent link="mid3"/>
    <child link="arm3"/>
    <origin rpy="0 0 0" xyz="0 0 0"/> 
    <axis xyz="0.309 0.951 0"/>
    <limit effort="1000" lower="-.5" upper=".5" velocity="50"/>
    <dynamics damping="0.001" friction="0.001"/>
  </joint>
  <link name="arm3">
    <inertial>
      <mass value="50"/>
      <inertia ixx="1E-01" ixy="0" ixz="0" iyy="1E01" iyz="0" izz="1E-02"/>
      <origin xyz="-0.6 0.200 0." />
    </inertial>
    <visual>
      <origin rpy="0 0 0" xyz="0.295 -0.100 0"/>
      <geometry>
        <mesh filename="package://starfish-soft/arm3.stl" scale="1 1 1"/>
      </geometry>
    </visual>
    <collision>
      <origin rpy="0 0 0" xyz="0.295 -0.100 0"/>
      <geometry>
        <mesh filename="package://starfish-soft/arm3.stl" scale="1 1 1" />
      </geometry>
    </collision>
  </link>


  <joint name="joint41" type="revolute">
    <parent link="central"/>
    <child link="mid4"/>
    <origin rpy="0 0 0" xyz="0.247 -0.228 0"/> 
    <axis xyz="0 0 1"/>
    <limit effort="1000" lower="-.5" upper=".5" velocity="50"/>
    <dynamics damping="0.001" friction="0.001"/>
  </joint>
  <link name="mid4">
    <inertial>
      <mass value="1"/>
      <inertia ixx="1E-03" ixy="0" ixz="0" iyy="1E-03" iyz="0" izz="1E-03"/>
      <origin xyz="0 0 0." />
    </inertial>
    <visual>
      <origin rpy="0 0 0" xyz="0 0 0"/>
      <geometry>
        <box size="0.01 0.01 0.01" />
      </geometry>
    </visual>
    <collision>
      <origin rpy="0 0 0" xyz="0 0 0"/>
      <geometry>
        <box size="0.01 0.01 0.01" />
      </geometry>
    </collision>
  </link>

  <joint name="joint42" type="revolute">
    <parent link="mid4"/>
    <child link="arm4"/>
    <origin rpy="0 0 0" xyz="0 0 0"/> 
    <axis xyz="-0.669 -0.743 0"/>
    <limit effort="1000" lower="-.5" upper=".5" velocity="50"/>
    <dynamics damping="0.001" friction="0.001"/>
  </joint>
  <link name="arm4">
    <inertial>
      <mass value="50"/>
      <inertia ixx="5E00" ixy="0" ixz="0" iyy="2E01" iyz="0" izz="1E-02"/>
      <origin xyz="0.50 -0.46 0." />
    </inertial>
    <visual>
      <origin rpy="0 0 0" xyz="-0.247 0.228 0"/>
      <geometry>
        <mesh filename="package://starfish-soft/arm4.stl" scale="1 1 1"/>
      </geometry>
    </visual>
    <collision>
      <origin rpy="0 0 0" xyz="-0.247 0.228 0"/>
      <geometry>
        <mesh filename="package://starfish-soft/arm4.stl" scale="1 1 1" />
      </geometry>
    </collision>
  </link>


  <joint name="joint51" type="revolute">
    <parent link="central"/>
    <child link="mid5"/>
    <origin rpy="0 0 0" xyz="-0.186 -0.274 0"/> 
    <axis xyz="0 0 1"/>
    <limit effort="1000" lower="-.5" upper=".5" velocity="50"/>
    <dynamics damping="0.001" friction="0.001"/>
  </joint>
  <link name="mid5">
    <inertial>
      <mass value="1"/>
      <inertia ixx="1E-03" ixy="0" ixz="0" iyy="1E-03" iyz="0" izz="1E-03"/>
      <origin xyz="0 0 0." />
    </inertial>
    <visual>
      <origin rpy="0 0 0" xyz="0 0 0"/>
      <geometry>
        <box size="0.01 0.01 0.01" />
      </geometry>
    </visual>
    <collision>
      <origin rpy="0 0 0" xyz="0 0 0"/>
      <geometry>
        <box size="0.01 0.01 0.01" />
      </geometry>
    </collision>
  </link>

  <joint name="joint52" type="revolute">
    <parent link="mid5"/>
    <child link="arm5"/>
    <origin rpy="0 0 0" xyz="0 0 0"/> 
    <axis xyz="-0.829 0.559 0"/>
    <limit effort="1000" lower="-.5" upper=".5" velocity="50"/>
    <dynamics damping="0.001" friction="0.001"/>
  </joint>
  <link name="arm5">
    <inertial>
      <mass value="50"/>
      <inertia ixx="5E00" ixy="0" ixz="0" iyy="2E01" iyz="0" izz="1E-02"/>
      <origin xyz="-0.37 -0.55 0." />
    </inertial>
    <visual>
      <origin rpy="0 0 0" xyz="0.186 0.274 0"/>
      <geometry>
        <mesh filename="package://starfish-soft/arm5.stl" scale="1 1 1"/>
      </geometry>
    </visual>
    <collision>
      <origin rpy="0 0 0" xyz="0.186 0.274 0"/>
      <geometry>
        <mesh filename="package://starfish-soft/arm5.stl" scale="1 1 1" />
      </geometry>
    </collision>
  </link>

</robot>