<?xml version="1.0"?>
<robot name="starfish">

  <link name="central">
    <visual>
      <origin rpy="0 0 0" xyz="0 0 0"/>
      <geometry>
        <mesh filename="package://starfish-soft/central.stl" scale="1 1 1"/>
      </geometry>
    </visual>
    <collision>
      <origin rpy="0 0 0" xyz="0 0 0"/>
      <geometry>
        <mesh filename="package://starfish-soft/central.stl" scale="1 1 1" />
      </geometry>
    </collision>
  </link>

  <joint name="joint1" type="revolute">
    <parent link="central"/>
    <child link="arm1"/>
    <origin rpy="0 0 0" xyz="0 0.368 0"/> 
    <axis xyz="0.99939 0.0349 0"/> 
    <limit effort="1000" lower="-.5" upper=".5" velocity="50"/>
    <dynamics damping="0.001" friction="0.001"/>
  </joint>

  <link name="arm1">
    <visual>
      <origin rpy="0 0 0" xyz="0 -0.368 0"/>
      <geometry>
        <mesh filename="package://starfish-soft/arm1.stl" scale="1 1 1"/>
      </geometry>
    </visual>
    <collision>
      <origin rpy="0 0 0" xyz="0 -0.368 0"/>
      <geometry>
        <mesh filename="package://starfish-soft/arm1.stl" scale="1 1 1" />
      </geometry>
    </collision>
  </link>

  <joint name="joint2" type="revolute">
    <parent link="central"/>
    <child link="arm2"/>
    <origin rpy="0 0 0" xyz="0.274 0.112 0"/> 
    <axis xyz="0.37415 -0.92718 0"/>
    <limit effort="1000" lower="-.5" upper=".5" velocity="50"/>
    <dynamics damping="0.001" friction="0.001"/>
  </joint>

  <link name="arm2">
    <visual>
      <origin rpy="0 0 0" xyz="-0.274 -0.112 0"/>
      <geometry>
        <mesh filename="package://starfish-soft/arm2.stl" scale="1 1 1"/>
      </geometry>
    </visual>
    <collision>
      <origin rpy="0 0 0" xyz="-0.274 -0.112 0"/>
      <geometry>
        <mesh filename="package://starfish-soft/arm2.stl" scale="1 1 1" />
      </geometry>
    </collision>
  </link>

  <joint name="joint3" type="revolute">
    <parent link="central"/>
    <child link="arm3"/>
    <origin rpy="0 0 0" xyz="-0.295 0.100 0"/> 
    <axis xyz="0.309 0.951 0"/>
    <limit effort="1000" lower="-.5" upper=".5" velocity="50"/>
    <dynamics damping="0.001" friction="0.001"/>
  </joint>

  <link name="arm3">
    <visual>
      <origin rpy="0 0 0" xyz="0.295 -0.100 0"/>
      <geometry>
        <mesh filename="package://starfish-soft/arm3.stl" scale="1 1 1"/>
      </geometry>
    </visual>
    <collision>
      <origin rpy="0 0 0" xyz="0.295 -0.100 0"/>
      <geometry>
        <mesh filename="package://starfish-soft/arm3.stl" scale="1 1 1" />
      </geometry>
    </collision>
  </link>

  <joint name="joint4" type="revolute">
    <parent link="central"/>
    <child link="arm4"/>
    <origin rpy="0 0 0" xyz="0.247 -0.228 0"/> 
    <axis xyz="-0.669 -0.743 0"/>
    <limit effort="1000" lower="-.5" upper=".5" velocity="50"/>
    <dynamics damping="0.001" friction="0.001"/>
  </joint>

  <link name="arm4">
    <visual>
      <origin rpy="0 0 0" xyz="-0.247 0.228 0"/>
      <geometry>
        <mesh filename="package://starfish-soft/arm4.stl" scale="1 1 1"/>
      </geometry>
    </visual>
    <collision>
      <origin rpy="0 0 0" xyz="-0.247 0.228 0"/>
      <geometry>
        <mesh filename="package://starfish-soft/arm4.stl" scale="1 1 1" />
      </geometry>
    </collision>
  </link>

  <joint name="joint5" type="revolute">
    <parent link="central"/>
    <child link="arm5"/>
    <origin rpy="0 0 0" xyz="-0.186 -0.274 0"/> 
    <axis xyz="-0.829 0.559 0"/>
    <limit effort="1000" lower="-.5" upper=".5" velocity="50"/>
    <dynamics damping="0.001" friction="0.001"/>
  </joint>

  <link name="arm5">
    <visual>
      <origin rpy="0 0 0" xyz="0.186 0.274 0"/>
      <geometry>
        <mesh filename="package://starfish-soft/arm5.stl" scale="1 1 1"/>
      </geometry>
    </visual>
    <collision>
      <origin rpy="0 0 0" xyz="0.186 0.274 0"/>
      <geometry>
        <mesh filename="package://starfish-soft/arm5.stl" scale="1 1 1" />
      </geometry>
    </collision>
  </link>

</robot>